#VRML_SIM R2019a utf8
WorldInfo {
}
Viewpoint {
  orientation -0.035868265953982924 0.9985424830677531 0.04032836478634492 1.5255814246168629
  position 0.6337684167686864 0.135630333755162 0.10630231573658333
}
TexturedBackground {
}
TexturedBackgroundLight {
}
Floor {
}
Robot {
  children [
    Solid {
      translation 0 0.09499999999999999 0
      children [
        Shape {
          appearance PBRAppearance {
            baseColor 0.5411764705882353 0.8862745098039215 0.20392156862745098
          }
          geometry Box {
            size 0.25 0.1 0.07
          }
        }
        HingeJoint {
          jointParameters HingeJointParameters {
            axis 0 0 1
          }
          endPoint Solid {
            translation 0.0625 0 0.045
            rotation 0.9233210835077168 -0.27154987877422654 -0.2715489644388988 1.6504934274790264
            children [
              Shape {
                appearance PBRAppearance {
                }
                geometry Cylinder {
                  height 0.02
                  radius 0.075
                }
              }
            ]
          }
        }
      ]
    }
  ]
}
