#VRML_SIM R2019a utf8
WorldInfo {
}
Viewpoint {
  orientation -0.1096212569968474 0.9894039313620496 0.09520000325499853 1.3742243454274254
  position 0.4004015338707077 0.15709751412387063 0.14047140534873415
}
TexturedBackground {
}
TexturedBackgroundLight {
}
Floor {
}
Robot {
  translation 0 0.075 0
  children [
    DEF ROBOD_BODY Shape {
      appearance PBRAppearance {
        baseColor 0.6431372549019608 0 0
      }
      geometry DEF G_BODY Box {
        size 0.25 0.07 0.1
      }
    }
    DEF WHEEL1_JOINT HingeJoint {
      jointParameters HingeJointParameters {
        axis 0 0 1
        anchor -0.05 0 0.06
      }
      endPoint DEF WHEEL1 Solid {
        translation -0.05 0 0.06
        rotation -1 0 0 1.5707996938995745
        children [
          Shape {
            appearance PBRAppearance {
              baseColor 0.9333333333333333 0.9333333333333333 0.9254901960784314
              roughness 1
              metalness 0
            }
            geometry DEF G_WHEEL Cylinder {
              height 0.02
              radius 0.075
            }
          }
        ]
        boundingObject USE G_WHEEL
        physics Physics {
        }
      }
    }
  ]
  boundingObject USE G_BODY
  physics Physics {
  }
  controller "Robot1"
}
