#VRML_SIM R2019a utf8
WorldInfo {
}
Viewpoint {
  orientation -0.4381955861511258 -0.8853017140407538 -0.15564544128940883 0.8005004955421
  position -0.5149216321402383 0.34170978951223674 0.5656828792970209
}
TexturedBackground {
}
TexturedBackgroundLight {
}
Floor {
}
Robot {
  children [
    Solid {
      children [
        Shape {
          appearance PBRAppearance {
          }
          geometry Box {
            size 0.25 0.1 0.07
          }
        }
        HingeJoint {
          jointParameters HingeJointParameters {
          }
          endPoint Solid {
            translation 0.08 0 0
          }
        }
      ]
    }
  ]
}
